Workbook

Sheet Notas Fiscais
A1: Nº da Nota | B1: Unidade | C1: Data de Emissão | D1: Valor ERP (R$) | E1: Valor Nota Fiscal (R$) | F1: Diferença (R$) | G1: Status | H1: Tipo de Divergência | I1: Dias de Atraso | J1: Valor em Risco (R$)
A2: NF-20260616-0001 | B2: UN Oeste | C2: 46189 | D2: 207670.57 | F2: =IF(E2="","",E2-D2) | G2: Pendente | I2: 0 | J2: =IF(G2="Divergente",ABS(F2),0) -> 0
A3: NF-20260616-0002 | B3: UN Centro | C3: 46189 | D3: 72358.52 | E3: 72358.52 | F3: =IF(E3="","",E3-D3) -> 0 | G3: Conciliado | I3: 0 | J3: =IF(G3="Divergente",ABS(F3),0) -> 0
A4: NF-20260616-0003 | B4: UN Centro | C4: 46189 | D4: 126614.18 | E4: 126614.18 | F4: =IF(E4="","",E4-D4) -> 0 | G4: Divergente | H4: Atraso na carga | I4: 2 | J4: =IF(G4="Divergente",ABS(F4),0) -> 0
A5: NF-20260616-0004 | B5: UN Oeste | C5: 46189 | D5: 70820.86 | E5: 70820.86 | F5: =IF(E5="","",E5-D5) -> 0 | G5: Conciliado | I5: 0 | J5: =IF(G5="Divergente",ABS(F5),0) -> 0
A6: NF-20260616-0005 | B6: UN Centro | C6: 46189 | D6: 85710.88 | E6: 85710.88 | F6: =IF(E6="","",E6-D6) -> 0 | G6: Conciliado | I6: 0 | J6: =IF(G6="Divergente",ABS(F6),0) -> 0
A7: NF-20260616-0006 | B7: UN Vale do Paraíba | C7: 46189 | D7: 292348.61 | E7: 292348.61 | F7: =IF(E7="","",E7-D7) -> 0 | G7: Divergente | H7: Atraso na carga | I7: 2 | J7: =IF(G7="Divergente",ABS(F7),0) -> 0
A8: NF-20260617-0007 | B8: UN Leste | C8: 46190 | D8: 280499.2 | E8: 280499.2 | F8: =IF(E8="","",E8-D8) -> 0 | G8: Divergente | H8: Atraso na carga | I8: 3 | J8: =IF(G8="Divergente",ABS(F8),0) -> 0
A9: NF-20260617-0008 | B9: UN Centro | C9: 46190 | D9: 83006.51 | E9: 83006.51 | F9: =IF(E9="","",E9-D9) -> 0 | G9: Conciliado | I9: 0 | J9: =IF(G9="Divergente",ABS(F9),0) -> 0
A10: NF-20260617-0009 | B10: UN Vale do Paraíba | C10: 46190 | D10: 111326.87 | E10: 111326.87 | F10: =IF(E10="","",E10-D10) -> 0 | G10: Conciliado | I10: 0 | J10: =IF(G10="Divergente",ABS(F10),0) -> 0
A11: NF-20260617-0010 | B11: UN Vale do Paraíba | C11: 46190 | D11: 114541.96 | E11: 117978.22 | F11: =IF(E11="","",E11-D11) -> 3436.26 | G11: Divergente | H11: Valor divergente | I11: 0 | J11: =IF(G11="Divergente",ABS(F11),0) -> 3436.26
A12: NF-20260617-0011 | B12: UN Centro | C12: 46190 | D12: 122681.42 | E12: 122681.42 | F12: =IF(E12="","",E12-D12) -> 0 | G12: Conciliado | I12: 0 | J12: =IF(G12="Divergente",ABS(F12),0) -> 0
A13: NF-20260618-0012 | B13: UN Norte | C13: 46191 | D13: 239520.84 | E13: 239520.84 | F13: =IF(E13="","",E13-D13) -> 0 | G13: Conciliado | I13: 0 | J13: =IF(G13="Divergente",ABS(F13),0) -> 0
A14: NF-20260618-0013 | B14: UN Norte | C14: 46191 | D14: 164895.15 | E14: 164895.15 | F14: =IF(E14="","",E14-D14) -> 0 | G14: Conciliado | I14: 0 | J14: =IF(G14="Divergente",ABS(F14),0) -> 0
A15: NF-20260618-0014 | B15: UN Vale do Paraíba | C15: 46191 | D15: 0 | E15: 380923.33 | F15: =IF(E15="","",E15-D15) -> 380923.33 | G15: Divergente | H15: Nota faltante na origem | I15: 0 | J15: =IF(G15="Divergente",ABS(F15),0) -> 380923.33
A16: NF-20260618-0015 | B16: UN Centro | C16: 46191 | D16: 252802.36 | E16: 252802.36 | F16: =IF(E16="","",E16-D16) -> 0 | G16: Conciliado | I16: 0 | J16: =IF(G16="Divergente",ABS(F16),0) -> 0
A17: NF-20260618-0016 | B17: UN Sul | C17: 46191 | D17: 159571.99 | E17: 159571.99 | F17: =IF(E17="","",E17-D17) -> 0 | G17: Conciliado | I17: 0 | J17: =IF(G17="Divergente",ABS(F17),0) -> 0
A18: NF-20260618-0017 | B18: UN Leste | C18: 46191 | D18: 0 | E18: 260369.77 | F18: =IF(E18="","",E18-D18) -> 260369.77 | G18: Divergente | H18: Nota faltante na origem | I18: 0 | J18: =IF(G18="Divergente",ABS(F18),0) -> 260369.77
A19: NF-20260618-0018 | B19: UN Oeste | C19: 46191 | D19: 449971.6 | E19: 449971.6 | F19: =IF(E19="","",E19-D19) -> 0 | G19: Conciliado | I19: 0 | J19: =IF(G19="Divergente",ABS(F19),0) -> 0
A20: NF-20260619-0019 | B20: UN Centro | C20: 46192 | D20: 287861.67 | E20: 287861.67 | F20: =IF(E20="","",E20-D20) -> 0 | G20: Conciliado | I20: 0 | J20: =IF(G20="Divergente",ABS(F20),0) -> 0
A21: NF-20260619-0020 | B21: UN Norte | C21: 46192 | D21: 183055.06 | E21: 183055.06 | F21: =IF(E21="","",E21-D21) -> 0 | G21: Conciliado | I21: 0 | J21: =IF(G21="Divergente",ABS(F21),0) -> 0
A22: NF-20260619-0021 | B22: UN Sul | C22: 46192 | D22: 290952.84 | E22: 290952.84 | F22: =IF(E22="","",E22-D22) -> 0 | G22: Conciliado | I22: 0 | J22: =IF(G22="Divergente",ABS(F22),0) -> 0
A23: NF-20260619-0022 | B23: UN Leste | C23: 46192 | D23: 455106.49 | E23: 455106.49 | F23: =IF(E23="","",E23-D23) -> 0 | G23: Conciliado | I23: 0 | J23: =IF(G23="Divergente",ABS(F23),0) -> 0
A24: NF-20260620-0023 | B24: UN Leste | C24: 46193 | D24: 359021.7 | E24: 359021.7 | F24: =IF(E24="","",E24-D24) -> 0 | G24: Conciliado | I24: 0 | J24: =IF(G24="Divergente",ABS(F24),0) -> 0
A25: NF-20260620-0024 | B25: UN Centro | C25: 46193 | D25: 476893.17 | E25: 476893.17 | F25: =IF(E25="","",E25-D25) -> 0 | G25: Conciliado | I25: 0 | J25: =IF(G25="Divergente",ABS(F25),0) -> 0
A26: NF-20260620-0025 | B26: UN Norte | C26: 46193 | D26: 352482.51 | E26: 352482.51 | F26: =IF(E26="","",E26-D26) -> 0 | G26: Conciliado | I26: 0 | J26: =IF(G26="Divergente",ABS(F26),0) -> 0
A27: NF-20260620-0026 | B27: UN Norte | C27: 46193 | D27: 40153.32 | E27: 40153.32 | F27: =IF(E27="","",E27-D27) -> 0 | G27: Conciliado | I27: 0 | J27: =IF(G27="Divergente",ABS(F27),0) -> 0
A28: NF-20260621-0027 | B28: UN Centro | C28: 46194 | D28: 0 | E28: 82693.11 | F28: =IF(E28="","",E28-D28) -> 82693.11 | G28: Divergente | H28: Nota faltante na origem | I28: 0 | J28: =IF(G28="Divergente",ABS(F28),0) -> 82693.11
A29: NF-20260621-0028 | B29: UN Oeste | C29: 46194 | D29: 362263.52 | E29: 362263.52 | F29: =IF(E29="","",E29-D29) -> 0 | G29: Conciliado | I29: 0 | J29: =IF(G29="Divergente",ABS(F29),0) -> 0
A30: NF-20260621-0029 | B30: UN Sul | C30: 46194 | D30: 66261.59 | E30: 66261.59 | F30: =IF(E30="","",E30-D30) -> 0 | G30: Conciliado | I30: 0 | J30: =IF(G30="Divergente",ABS(F30),0) -> 0
A31: NF-20260621-0030 | B31: UN Centro | C31: 46194 | D31: 155027.61 | E31: 155027.61 | F31: =IF(E31="","",E31-D31) -> 0 | G31: Divergente | H31: Atraso na carga | I31: 6 | J31: =IF(G31="Divergente",ABS(F31),0) -> 0
A32: NF-20260621-0031 | B32: UN Norte | C32: 46194 | D32: 347878.52 | E32: 347878.52 | F32: =IF(E32="","",E32-D32) -> 0 | G32: Conciliado | I32: 0 | J32: =IF(G32="Divergente",ABS(F32),0) -> 0
A33: NF-20260622-0032 | B33: UN Oeste | C33: 46195 | D33: 97914.41 | E33: 195828.82 | F33: =IF(E33="","",E33-D33) -> 97914.41 | G33: Divergente | H33: Nota duplicada | I33: 0 | J33: =IF(G33="Divergente",ABS(F33),0) -> 97914.41
A34: NF-20260622-0033 | B34: UN Vale do Paraíba | C34: 46195 | D34: 135001.24 | E34: 135001.24 | F34: =IF(E34="","",E34-D34) -> 0 | G34: Conciliado | I34: 0 | J34: =IF(G34="Divergente",ABS(F34),0) -> 0
A35: NF-20260622-0034 | B35: UN Centro | C35: 46195 | D35: 112054.29 | E35: 112054.29 | F35: =IF(E35="","",E35-D35) -> 0 | G35: Conciliado | I35: 0 | J35: =IF(G35="Divergente",ABS(F35),0) -> 0
A36: NF-20260622-0035 | B36: UN Oeste | C36: 46195 | D36: 218525.93 | E36: 218525.93 | F36: =IF(E36="","",E36-D36) -> 0 | G36: Conciliado | I36: 0 | J36: =IF(G36="Divergente",ABS(F36),0) -> 0
A37: NF-20260622-0036 | B37: UN Centro | C37: 46195 | D37: 173375.26 | E37: 168174 | F37: =IF(E37="","",E37-D37) -> -5201.26 | G37: Divergente | H37: Valor divergente | I37: 0 | J37: =IF(G37="Divergente",ABS(F37),0) -> 5201.26
A38: NF-20260622-0037 | B38: UN Vale do Paraíba | C38: 46195 | D38: 389042.9 | E38: 389042.9 | F38: =IF(E38="","",E38-D38) -> 0 | G38: Conciliado | I38: 0 | J38: =IF(G38="Divergente",ABS(F38),0) -> 0
A39: NF-20260622-0038 | B39: UN Sul | C39: 46195 | D39: 207354.01 | E39: 207354.01 | F39: =IF(E39="","",E39-D39) -> 0 | G39: Conciliado | I39: 0 | J39: =IF(G39="Divergente",ABS(F39),0) -> 0
A40: NF-20260623-0039 | B40: UN Leste | C40: 46196 | D40: 115774.29 | E40: 115774.29 | F40: =IF(E40="","",E40-D40) -> 0 | G40: Conciliado | I40: 0 | J40: =IF(G40="Divergente",ABS(F40),0) -> 0
...

Sheet Resumo
A1: Resumo · V360 Radar Fiscal
A3: Total de Notas (30 dias) | B3: =COUNTA('Notas Fiscais'!A2:A174) -> 173
A4: Notas Conciliadas | B4: =COUNTIF('Notas Fiscais'!G2:G174,"Conciliado") -> 132
A5: Notas Divergentes | B5: =COUNTIF('Notas Fiscais'!G2:G174,"Divergente") -> 31
A6: Notas Pendentes | B6: =COUNTIF('Notas Fiscais'!G2:G174,"Pendente") -> 10
A7: Taxa de Conciliação | B7: =B4/B3 -> 0.76300578
A8: Valor Total em Risco (R$) | B8: =SUM('Notas Fiscais'!J2:J174) -> 4294876.8
A9: Dias de Atraso (média p/ notas atrasadas) | B9: =IFERROR(AVERAGEIF('Notas Fiscais'!I2:I174,">0"),0) -> 3.5555556
A10: Dados simulados para prototipagem de dashboard (Power BI). Gerado automaticamente.
